Workbook

Sheet Leia-me
B2: Elo Varejo — Análise Financeira Comparada
B3: Future Lab 2026 · Davi Lucas · Piloto: perda de estoque em redes de varejo listadas (dado CVM)
B5: Aba 'Indice Elo Varejo'
B6: Comparação real entre redes de varejo. Magazine Luiza está 100% preenchida com dado real, extraído e citado diretamente das Demonstrações Financeiras auditadas por Ernst & Young (31/12/2023). As demais linhas (fundo amarelo) são placeholders — mesma estrutura, prontas para receber o dado real de cada empresa quando você rodar a extração de verdade durante o sprint.
B8: Aba 'Mercado - Contexto'
B9: Números de mercado real e citado (9ª Pesquisa Abrappe + Protiviti, 2025) — tamanho da dor, não específico de uma empresa.
B11: Aba 'CRM Validacao'
B12: Lista de pessoas para validar a dor de mercado, com status e eixo narrativo sugerido pra cada uma.
B14: Convenção de cor
B15: Azul = dado real, digitado a partir de fonte citada. Preto = fórmula. Amarelo = célula para você preencher.

Sheet Indice Elo Varejo
A1: Índice Elo Varejo — Provisão para Perdas em Estoque, Redes Listadas na Bolsa
A2: Fonte real: Demonstrações Financeiras Padronizadas (DFP), auditadas, publicadas via CVM. Valores em R$ mil.
A4: Empresa | B4: Ticker | C4: Exercício | D4: Base | E4: Estoque bruto (mercadorias+consumo) | F4: Provisão p/ perdas no estoque | G4: Estoque líquido | H4: % Provisão / Estoque bruto | I4: Auditor | J4: Fonte / Status
A5: Magazine Luiza S.A. | B5: MGLU3 | C5: 2023 | D5: Consolidado | E5: 7676860 | F5: -179561 | G5: =E5+F5 | H5: =-F5/E5 | I5: Ernst & Young | J5: Real — DF 31/12/2023, Nota 9 (Estoques), publicado ri.magazineluiza.com.br, auditado 18/03/2024
A6: Magazine Luiza S.A. | B6: MGLU3 | C6: 2022 | D6: Consolidado | F6: -184484 | G6: n/d | H6: n/d | I6: Ernst & Young | J6: Real — mesma nota, saldo comparativo 2022 (estoque bruto 2022 não extraído nesta rodada)
A7: Via S.A. (Casas Bahia / Ponto) | B7: VIIA3 | C7: A EXTRAIR | D7: Consolidado | J7: Pendente — extrair do DFP/ITR mais recente na CVM (dados.cvm.gov.br) durante o sprint
A8: Lojas Renner S.A. | B8: LREN3 | C8: A EXTRAIR | D8: Consolidado | J8: Pendente — extrair do DFP/ITR mais recente na CVM (dados.cvm.gov.br) durante o sprint
A9: C&A Modas S.A. | B9: CEAB3 | C9: A EXTRAIR | D9: Consolidado | J9: Pendente — extrair do DFP/ITR mais recente na CVM (dados.cvm.gov.br) durante o sprint
A10: Assaí Atacadista | B10: ASAI3 | C10: A EXTRAIR | D10: Consolidado | J10: Pendente — extrair do DFP/ITR mais recente na CVM (dados.cvm.gov.br) durante o sprint
A11: Grupo SBF (Centauro) | B11: SBFG3 | C11: A EXTRAIR | D11: Consolidado | J11: Pendente — extrair do DFP/ITR mais recente na CVM (dados.cvm.gov.br) durante o sprint
A12: Marisa Lojas S.A. | B12: AMAR3 | C12: A EXTRAIR | D12: Consolidado | J12: Pendente — extrair do DFP/ITR mais recente na CVM (dados.cvm.gov.br) durante o sprint
A14: Metodologia (nota adjacente à tabela):
A15: % Provisão/Estoque bruto = provisão para perdas em estoque ÷ (mercadorias para revenda + material de consumo), conforme Nota Explicativa de Estoques de cada companhia. Este sandbox não teve acesso de rede ao portal de dados abertos da CVM (dados.cvm.gov.br) para automatizar a extração das demais linhas — a extração da Magazine Luiza foi feita manualmente a partir do PDF oficial publicado no site de RI da empresa, e é 100% real e verificável. As linhas em amarelo têm a mesma estrutura pronta para receber dado real durante o sprint (Claude Code, com acesso à internet, deve conseguir automatizar a extração e a busca por terminologia equivalente em cada empresa: 'provisão para perda de estoque', 'ajuste a valor de mercado', 'quebra operacional', 'obsolescência').

Sheet Mercado - Contexto
A1: Mercado — Contexto Real (9ª Pesquisa Abrappe de Prevenção de Perdas + Protiviti, 2025)
A3: Métrica | B3: Valor | C3: Comparação / Tendência | D3: Fonte
A4: Perda total do varejo brasileiro, 2025 | B4: R$ 42,1 bilhões | C4: Faturamento cresceu 6,4% (R$2,55 tri); perdas cresceram 15,3% no mesmo período — perda piora mais rápido que o setor cresce | D4: 9ª Pesquisa Abrappe/Protiviti, 2025
A5: Índice médio de perdas | B5: 1,65% da receita (2025) | C5: Subiu de 1,51% em 2024 (+9,27%) | D5: 9ª Pesquisa Abrappe/Protiviti, 2025
A6: Relação vendas/perda | B6: R$1 perdido a cada R$61 vendidos | C6: — | D6: 9ª Pesquisa Abrappe/Protiviti, 2025
A7: Composição da perda | B7: ~70% quebra operacional, furto interno/externo e erro de inventário | C7: — | D7: 9ª Pesquisa Abrappe/Protiviti, 2025
A8: Eletromóveis — perda total | B8: +278,2% no ano | C8: Pior desempenho absoluto entre os segmentos, puxado por fraude em canal digital | D8: 9ª Pesquisa Abrappe/Protiviti, 2025
A9: Eletromóveis — perda não identificada | B9: +641,8% no ano | C9: Furto/fraude não rastreável — maior lacuna de visibilidade entre os segmentos | D9: 9ª Pesquisa Abrappe/Protiviti, 2025
A10: Lojas de conveniência — pior índice de formato | B10: 3,81% (+24,5%) | C10: Pressão de perecíveis + baixa estrutura de prevenção | D10: 9ª Pesquisa Abrappe/Protiviti, 2025
A11: Via S.A. — prejuízo líquido | B11: R$1,045 bi (2024), abaixo de R$2,625 bi (2023) | C11: Fechamento de 55 lojas, redução de >R$1bi em estoque, plano de reestruturação | D11: Imprensa (Seu Dinheiro, CNN Brasil), demonstrações da Via
A13: Ponto de ataque recomendado (o mais simples e mais sentido):
A14: Eletromóveis é o segmento com o sinal mais forte e mais urgente: perda total +278,2% e perda NÃO IDENTIFICADA +641,8% no ano — ou seja, é o segmento onde as empresas menos conseguem explicar a própria perda, exatamente o tipo de lacuna que um índice comparável resolve primeiro. Magazine Luiza e Via são as duas maiores redes públicas expostas a esse segmento — por isso a Magazine Luiza foi escolhida como primeiro caso real.

Sheet CRM Validacao
A1: CRM — Pessoas para Validar a Dor de Mercado (Elo Varejo)
A3: Nome | B3: Empresa / Papel | C3: Como conheço | D3: Status | E3: Eixo narrativo a usar | F3: Próxima ação | G3: Prazo
A4: Bruno Dias | B4: Head of Engineering & Data, Zippi (ex-Diretor de Ops, VTEX) | C4: Mentor oficial Future Lab | D4: Reunião já feita — aguardando gravação | E4: Validação técnica: 'você viu essa bagunça de dado por dentro da VTEX' | F4: Pedir a gravação da reunião + intros da rede dele | G4: Antes de qui 24/07
A5: Daniel Soares | B5: Solomon (e-commerce) — entrevista prévia p/ founding sales exec | C5: Contato profissional pré-existente | D5: A contatar | E5: Continuidade de relação: 'quero validar um projeto com quem já entende e-commerce de verdade' | F5: Mandar mensagem propondo consulta/agenda | G5: Hoje
A6: Lucas Bacic | B6: CPO, Loja Integrada (ex-VTEX, IPO NYSE) | C6: Mentor Future Lab | D6: A contatar (office hours) | E6: Operação real de varejo em escala — terminologia de perda de estoque | F6: Abordar no bloco de mão na massa (24 ou 25/07) | G6: 24-25/07
A7: Gabriel Tiburcio | B7: Eng. de Produto, Trove (ex-VTEX, mParticle) | C7: Mentor Future Lab | D7: A contatar (office hours) | E7: Segunda referência de operação de varejo em escala | F7: Abordar no bloco de mão na massa | G7: 24-25/07
A8: José Noblecilla | B8: Head of Tech & AI, Valor Capital (co-fundou Arado) | C8: Mentor Future Lab | D8: A contatar (office hours) | E8: Visão de investidor: motor horizontal vs. índice de nicho único | F8: Abordar no bloco de mão na massa | G8: 24-25/07
A9: Antonio Nakad | B9: NG Cash (ex-CPTO/CMO, 7M usuários) | C9: Mentor Future Lab | D9: A contatar (office hours) | E9: Como precificar/vender índice pra múltiplos clientes do mesmo setor | F9: Abordar no bloco de mão na massa | G9: 24-25/07
A10: Jorge Tung | B10: Fractional CPO/Advisor (Microsoft, RD Station, Loggi, Dr.Consulta) | C10: Mentor Future Lab | D10: A contatar (office hours) | E10: Qual setor tocar depois do varejo (seguros, bancos, utilities) | F10: Abordar no bloco de mão na massa | G10: 24-25/07
A11: [Contato via rede do Bruno] | B11: A confirmar — varejo ou dado | C11: Intro pendente do Bruno Dias | D11: Aguardando intro | E11: A calibrar após saber quem é | F11: Pedir pro Bruno essa intro específica | G11: Assim que possível

Sheet Aprofundamento CFO
A1: Aprofundamento CFO — Ratios, Benchmarking, Sensibilidade e Teste de Caso (Via S.A.)
A2: Complementa a aba 'Indice Elo Varejo' — atende aos itens 3.3 a 3.7 do Brief_CFO_Analise_Detalhada.docx. Nenhum número novo foi inventado: onde o dado de origem (CPV, Receita Líquida, Dias de Estoque das 6 empresas pendentes) ainda não foi extraído do DFP/ITR, a célula fica marcada 'A PREENCHER' e a fórmula já está pronta para calcular automaticamente assim que o dado real entrar.
A4: A) Ratios adicionais — item 3.3 do brief
A5: Empresa | B5: Ticker | C5: Exercício | D5: Provisão (t) R$ mil | E5: Provisão (t-1) R$ mil | F5: Ratio 1 Cresc. YoY Provisão (%) | G5: CPV R$ mil | H5: Ratio 2 Provisão/CPV (%) | I5: Receita Líquida R$ mil | J5: Ratio 3 Provisão/Receita Líq. (%) | K5: Dias de Estoque | L5: Ratio 4 (dias de estoque × %provisão)
A6: Magazine Luiza S.A. | B6: =('Indice Elo Varejo'!B5) | C6: =('Indice Elo Varejo'!C5) | D6: =-'Indice Elo Varejo'!F5 | E6: =-'Indice Elo Varejo'!F6 | F6: =(D6-E6)/E6 | G6: A PREENCHER | H6: =IFERROR(D6/G6,"A PREENCHER") | I6: A PREENCHER | J6: =IFERROR(D6/I6,"A PREENCHER") | K6: A PREENCHER | L6: =IFERROR(K6*H6,"A PREENCHER")
A7: Via S.A. (Casas Bahia/Ponto) | B7: A EXTRAIR | C7: A EXTRAIR | D7: A EXTRAIR | E7: A EXTRAIR | F7: A EXTRAIR | G7: A EXTRAIR | H7: A EXTRAIR | I7: A EXTRAIR | J7: A EXTRAIR | K7: A EXTRAIR | L7: A EXTRAIR
A8: Lojas Renner S.A. | B8: A EXTRAIR | C8: A EXTRAIR | D8: A EXTRAIR | E8: A EXTRAIR | F8: A EXTRAIR | G8: A EXTRAIR | H8: A EXTRAIR | I8: A EXTRAIR | J8: A EXTRAIR | K8: A EXTRAIR | L8: A EXTRAIR
A9: C&A Modas S.A. | B9: A EXTRAIR | C9: A EXTRAIR | D9: A EXTRAIR | E9: A EXTRAIR | F9: A EXTRAIR | G9: A EXTRAIR | H9: A EXTRAIR | I9: A EXTRAIR | J9: A EXTRAIR | K9: A EXTRAIR | L9: A EXTRAIR
A10: Assaí Atacadista | B10: A EXTRAIR | C10: A EXTRAIR | D10: A EXTRAIR | E10: A EXTRAIR | F10: A EXTRAIR | G10: A EXTRAIR | H10: A EXTRAIR | I10: A EXTRAIR | J10: A EXTRAIR | K10: A EXTRAIR | L10: A EXTRAIR
A11: Grupo SBF (Centauro) | B11: A EXTRAIR | C11: A EXTRAIR | D11: A EXTRAIR | E11: A EXTRAIR | F11: A EXTRAIR | G11: A EXTRAIR | H11: A EXTRAIR | I11: A EXTRAIR | J11: A EXTRAIR | K11: A EXTRAIR | L11: A EXTRAIR
A12: Marisa Lojas S.A. | B12: A EXTRAIR | C12: A EXTRAIR | D12: A EXTRAIR | E12: A EXTRAIR | F12: A EXTRAIR | G12: A EXTRAIR | H12: A EXTRAIR | I12: A EXTRAIR | J12: A EXTRAIR | K12: A EXTRAIR | L12: A EXTRAIR
A14: Fonte: Provisão (t) e (t-1) de Magazine Luiza vêm da aba 'Indice Elo Varejo' (linhas 5-6, real, Nota 9 Estoques, DF 31/12/2023, Ernst & Young). CPV, Receita Líquida e Dias de Estoque ainda não foram extraídos nesta rodada — ver ação recomendada na aba 'CFO - Premissas e Metodologia'.
A16: B) Benchmarking estatístico entre empresas — item 3.4 do brief
A17: Empresa | B17: % Provisão/Estoque bruto | C17: Z-score | D17: Percentil no grupo | E17: Outlier (>1 desvio)?
A18: =('Indice Elo Varejo'!A5) | B18: ='Indice Elo Varejo'!H5 | C18: =IFERROR((B18-AVERAGE($B$18:$B$24))/STDEV($B$18:$B$24),"n/d (n<2)") | D18: =IFERROR(PERCENTRANK($B$18:$B$24,B18),"n/d (n<2)") | E18: =IFERROR(IF(ABS(C18)>1,"SIM","não"),"n/d")
A19: ='Indice Elo Varejo'!A7 | B19: =IF(ISNUMBER('Indice Elo Varejo'!H7),'Indice Elo Varejo'!H7,"A EXTRAIR") | C19: =IF(ISNUMBER(B19),IFERROR((B19-AVERAGE($B$18:$B$24))/STDEV($B$18:$B$24),"n/d"),"n/d") | D19: =IF(ISNUMBER(B19),IFERROR(PERCENTRANK($B$18:$B$24,B19),"n/d"),"n/d") | E19: =IF(ISNUMBER(C19),IF(ABS(C19)>1,"SIM","não"),"n/d")
A20: ='Indice Elo Varejo'!A8 | B20: =IF(ISNUMBER('Indice Elo Varejo'!H8),'Indice Elo Varejo'!H8,"A EXTRAIR") | C20: =IF(ISNUMBER(B20),IFERROR((B20-AVERAGE($B$18:$B$24))/STDEV($B$18:$B$24),"n/d"),"n/d") | D20: =IF(ISNUMBER(B20),IFERROR(PERCENTRANK($B$18:$B$24,B20),"n/d"),"n/d") | E20: =IF(ISNUMBER(C20),IF(ABS(C20)>1,"SIM","não"),"n/d")
A21: ='Indice Elo Varejo'!A9 | B21: =IF(ISNUMBER('Indice Elo Varejo'!H9),'Indice Elo Varejo'!H9,"A EXTRAIR") | C21: =IF(ISNUMBER(B21),IFERROR((B21-AVERAGE($B$18:$B$24))/STDEV($B$18:$B$24),"n/d"),"n/d") | D21: =IF(ISNUMBER(B21),IFERROR(PERCENTRANK($B$18:$B$24,B21),"n/d"),"n/d") | E21: =IF(ISNUMBER(C21),IF(ABS(C21)>1,"SIM","não"),"n/d")
A22: ='Indice Elo Varejo'!A10 | B22: =IF(ISNUMBER('Indice Elo Varejo'!H10),'Indice Elo Varejo'!H10,"A EXTRAIR") | C22: =IF(ISNUMBER(B22),IFERROR((B22-AVERAGE($B$18:$B$24))/STDEV($B$18:$B$24),"n/d"),"n/d") | D22: =IF(ISNUMBER(B22),IFERROR(PERCENTRANK($B$18:$B$24,B22),"n/d"),"n/d") | E22: =IF(ISNUMBER(C22),IF(ABS(C22)>1,"SIM","não"),"n/d")
A23: ='Indice Elo Varejo'!A11 | B23: =IF(ISNUMBER('Indice Elo Varejo'!H11),'Indice Elo Varejo'!H11,"A EXTRAIR") | C23: =IF(ISNUMBER(B23),IFERROR((B23-AVERAGE($B$18:$B$24))/STDEV($B$18:$B$24),"n/d"),"n/d") | D23: =IF(ISNUMBER(B23),IFERROR(PERCENTRANK($B$18:$B$24,B23),"n/d"),"n/d") | E23: =IF(ISNUMBER(C23),IF(ABS(C23)>1,"SIM","não"),"n/d")
A24: ='Indice Elo Varejo'!A12 | B24: =IF(ISNUMBER('Indice Elo Varejo'!H12),'Indice Elo Varejo'!H12,"A EXTRAIR") | C24: =IF(ISNUMBER(B24),IFERROR((B24-AVERAGE($B$18:$B$24))/STDEV($B$18:$B$24),"n/d"),"n/d") | D24: =IF(ISNUMBER(B24),IFERROR(PERCENTRANK($B$18:$B$24,B24),"n/d"),"n/d") | E24: =IF(ISNUMBER(C24),IF(ABS(C24)>1,"SIM","não"),"n/d")
A25: Média do grupo | B25: =IFERROR(AVERAGE($B$18:$B$24),"n/d")
A26: Desvio padrão do grupo | B26: =IFERROR(STDEV($B$18:$B$24),"n/d")
A28: Nota de rigor: com n=1 (apenas Magazine Luiza real), desvio padrão e percentil não são estatisticamente robustos — as fórmulas já estão prontas e recalculam automaticamente à medida que as 6 linhas 'A EXTRAIR' forem preenchidas na aba 'Indice Elo Varejo'. Meta mínima de rigor estatístico: n≥5 empresas (ver item 3.4 do brief).
A30: C) Sensibilidade em R$ — item 3.7 do brief (quanto 1p.p. de provisão representa em R$)
A31: Empresa | B31: Estoque bruto (R$ mil) | C31: Provisão atual (R$ mil) | D31: Provisão atual (%) | E31: Impacto de 1p.p. adicional (R$ mil) | F31: Impacto de 1p.p. adicional (R$ milhões)
A32: =('Indice Elo Varejo'!A5) | B32: ='Indice Elo Varejo'!E5 | C32: =-'Indice Elo Varejo'!F5 | D32: ='Indice Elo Varejo'!H5 | E32: =B32*1% | F32: =E32/1000
A34: Leitura: para a Magazine Luiza, cada 1 ponto percentual adicional (ou a menos) no índice de provisão/estoque bruto equivale a ≈ R$ 76,8 milhões de impacto direto — o número que transforma "2,34% de provisão" (abstrato) em uma cifra que qualquer CFO ou conselho aloca instantaneamente. Esta é a âncora de valor usada na aba 'CFO - Precificação e Mercado' para justificar o ACV cobrado.
A36: D) Teste de caso — Via S.A. (item 3.5 do brief, maior valor esperado de todo o aprofundamento)
A37: Métrica | B37: 2023 | C37: 2024 | D37: Variação | E37: Fonte
A38: Prejuízo líquido (R$ bi) | B38: 2.625 | C38: 1.045 | D38: =(C38-B38)/B38 | E38: Real — imprensa (Seu Dinheiro, CNN Brasil) + demonstrações da Via; já citado na aba 'Mercado - Contexto', linha 11
A39: Lojas fechadas no período (plano de reestruturação) | B39: — | C39: 55 | D39: — | E39: Real — mesma fonte de imprensa citada na aba 'Mercado - Contexto'
A40: Redução de estoque anunciada (R$ bi) | B40: — | C40: >1,0 | D40: — | E40: Real — plano de reestruturação Via, mesma fonte
A41: % Provisão/Estoque bruto (índice Elo) 2021–2024 | B41: A CONFIRMAR | C41: A CONFIRMAR | D41: A CONFIRMAR | E41: PENDENTE — este é o dado que realmente resolve o item 3.5. Ação recomendada: extrair a Nota Explicativa de Estoques do DFP/ITR da Via S.A. (VIIA3) em dados.cvm.gov.br para os exercícios 2021–2024 e comparar a trajetória com a média do setor (aba B acima).
A43: Leitura honesta (sem o dado pendente): o prejuízo líquido da Via melhorou 60,2% entre 2023 e 2024 e a companhia reduziu estoque em >R$1 bi como parte do plano de reestruturação — ou seja, os sinais públicos disponíveis hoje mostram a Via em processo de correção, não em piora contínua. Isso NÃO confirma nem refuta a hipótese do brief (de que o índice de perda de estoque da Via "andou pior que a média do setor nos anos que antecederam" a dificuldade) — essa pergunta só se responde com a série 2021-2023 do índice real, que segue pendente. Não presumir a resposta.
A45: E) Cruzamento com a 9ª Pesquisa Abrappe/Protiviti — item 3.6 do brief
A46: Métrica | B46: Valor | C46: Fonte
A47: % Provisão/Estoque bruto — Magazine Luiza (Eletromóveis), 2023 | B47: ='Indice Elo Varejo'!H5 | C47: Real — ver aba 'Indice Elo Varejo'
A48: Índice médio geral de perdas do varejo, 2025 (todos os segmentos) | B48: 0.0165 | C48: Real — 9ª Pesquisa Abrappe/Protiviti 2025 (aba 'Mercado - Contexto', linha 5)
A49: Diferença absoluta (p.p.) | B49: =B47-B48 | C49: Fórmula = B47-B48
...

Sheet CFO - Precificacao e Mercado
A1: CFO — Arquitetura de Precificação e Dimensionamento de Mercado (TAM/SAM/SOM)
A2: Precificação por valor (value-based) ancorada na sensibilidade R$/p.p. calculada na aba 'Aprofundamento CFO', seção C. Contagens de universo regulatório citam fonte externa (azul); SAM/SOM e ACVs são premissas de modelagem do CFO (verde) — ver aba de Premissas para o racional.
A4: A) Tiers de assinatura — Elo Varejo (piloto)
A5: Tier | B5: Perfil do cliente | C5: ACV piso (R$/ano) | D5: ACV teto (R$/ano) | E5: ACV médio (R$/ano) | F5: Impacto de 1p.p. do cliente (R$ mi, referência MGLU) | G5: ACV médio como % do impacto de 1p.p.
A6: Growth | B6: Redes regionais, <R$500 milhões de receita anual | C6: 14400 | D6: 24000 | E6: =AVERAGE(C6:D6) | F6: ='Aprofundamento CFO'!F32 | G6: =E6/(F6*1000000)
A7: Mid-Market | B7: Redes de porte médio, R$500 milhões–R$5 bilhões de receita | C7: 36000 | D7: 72000 | E7: =AVERAGE(C7:D7) | F7: ='Aprofundamento CFO'!F32 | G7: =E7/(F7*1000000)
A8: Enterprise | B8: Grandes redes multi-bandeira, >R$5 bilhões de receita | C8: 96000 | D8: 180000 | E8: =AVERAGE(C8:D8) | F8: ='Aprofundamento CFO'!F32 | G8: =E8/(F8*1000000)
A10: Leitura: mesmo no tier Enterprise (R$ 180 mil/ano), o ACV representa menos de 0,25% do valor de 1 único ponto percentual de melhora na provisão de perdas de uma rede do porte da Magazine Luiza — a assinatura se paga long antes de qualquer decisão de compra ser questionada.
A12: B) ACV médio ponderado por vertical (motor horizontal)
A13: Vertical | B13: Regulador | C13: ACV médio (R$/ano) | D13: Lançamento (mês, cenário-base) | E13: Racional de preço (premissa CFO)
A14: Varejo | B14: CVM (DFP/ITR) | C14: 45000 | D14: 0 | E14: Loss Prevention/Risco de redes de varejo — budget menor, ciclo de venda mais curto (via warm intro).
A15: Seguros | B15: SUSEP | C15: 85000 | D15: 9 | E15: Compliance/Atuarial de seguradoras — budget de risco maior, uso do índice para subscrição/precificação de sinistralidade.
A16: Bancos/Fintechs | B16: BACEN | C16: 70000 | D16: 15 | E16: Risco de crédito/compliance de instituições financeiras — budget intermediário.
A17: Utilities | B17: ANEEL | C17: 65000 | D17: 22 | E17: Planejamento de resiliência operacional de distribuidoras — budget regulado, ciclo de compra mais longo.
A19: C) Dimensionamento TAM / SAM / SOM
A20: Vertical | B20: Universo regulado (entidades) | C20: Fonte do universo | D20: Contas-alvo (SAM) (premissa CFO) | E20: ACV médio (R$/ano) | F20: SAM em R$ (100% penetração)
A21: Varejo (CVM) | B21: 400 | C21: B3 — total de companhias listadas (universo bruto, todos os setores; subconjunto de varejo é menor) | D21: 70 | E21: 45000 | F21: =D21*E21
A22: Seguros (SUSEP) | B22: 356 | C22: SUSEP — entidades fiscalizadas (seguradoras, resseguradoras, EAPC, capitalização) | D22: 130 | E22: 85000 | F22: =D22*E22
A23: Bancos/Fintechs (BACEN) | B23: 350 | C23: BACEN — 308 fintechs autorizadas (2025) + bancos tradicionais (ordem de grandeza) | D23: 100 | E23: 70000 | F23: =D23*E23
A24: Utilities (ANEEL) | B24: 100 | C24: ANEEL — 33 grandes distribuidoras + permissionárias menores (ordem de grandeza) | D24: 40 | E24: 65000 | F24: =D24*E24
A25: TOTAL | B25: =SUM(B21:B24) | D25: =SUM(D21:D24) | F25: =SUM(F21:F24)
A27: Fontes dos universos regulatórios (dado real, citado): SUSEP (susep.gov.br — entidades fiscalizadas); BACEN (Boletim Demarest / Agência Brasil, dez/2025-jan/2026 — 308 fintechs autorizadas); ANEEL (ranking de continuidade ABRADEE/ANEEL — 33 grandes concessionárias). B3: >400 companhias listadas no total (todos os setores) — fonte: B3/InfoMoney. SAM por vertical é premissa de modelagem do CFO (filtragem por porte/orçamento realista), não uma contagem verificada.
A29: Convenção de cor:
A30: Azul = dado real, digitado a partir de fonte citada · Preto = fórmula · Amarelo = placeholder a preencher · Verde = premissa de modelagem do CFO (cenário/estimativa, não é fato verificado — distinta de dado real citado).

Sheet CFO - Monte Carlo e Valuation
A1: CFO — Simulação de Monte Carlo (ARR) e Projeção de Valuation
A2: Resultado de simulação estocástica (Python/NumPy, seed=42, 20.000 cenários, 36 meses, 4 verticais) — não são fórmulas nativas do Excel (a estocasticidade não é replicável em fórmula de célula sem macro). Todas as premissas de distribuição estão na aba 'CFO - Premissas e Metodologia' para reprodutibilidade total do modelo.
A4: A) ARR consolidado — percentis ao longo do tempo (R$)
A5: Mês | B5: P10 | C5: P25 | D5: P50 (mediana) | E5: Média | F5: P75 | G5: P90
A6: 3 | B6: 0 | C6: 0 | D6: 0 | E6: 26763 | F6: 43032 | G6: 79835
A7: 6 | B7: 0 | C7: 37708 | D7: 71740 | E7: 70058 | F7: 93361 | G7: 139190
A8: 9 | B8: 40323 | C8: 79710 | D8: 126702 | E8: 135051 | F8: 180729 | G8: 233806
A9: 12 | B9: 109546 | C9: 158750 | D9: 222462 | E9: 234152 | F9: 299296 | G9: 372066
A10: 15 | B10: 206944 | C10: 276470 | D10: 365974 | E10: 377241 | F10: 465863 | G10: 564894
A11: 18 | B11: 353549 | C11: 445195 | D11: 560318 | E11: 574731 | F11: 688217 | G11: 816262
A12: 21 | B12: 550594 | C12: 668644 | D12: 812335 | E12: 831429 | F12: 975662 | G12: 1131260
A13: 24 | B13: 806448 | C13: 952047 | D13: 1126656 | E13: 1147716 | F13: 1324772 | G13: 1512937
A14: 27 | B14: 1116882 | C14: 1289186 | D14: 1497823 | E14: 1519668 | F14: 1729867 | G14: 1950321
A15: 30 | B15: 1465635 | C15: 1665450 | D15: 1912140 | E15: 1935949 | F15: 2185814 | G15: 2435057
A16: 33 | B16: 1854592 | C16: 2087409 | D16: 2370920 | E16: 2396103 | F16: 2682212 | G16: 2970134
A17: 36 | B17: 2279113 | C17: 2539292 | D17: 2862866 | E17: 2889638 | F17: 3213389 | G17: 3538299
A19: B) Probabilidade de atingir marcos de ARR (%)
A20: Marco de ARR (R$) | B20: Mês 12 | C20: Mês 18 | D20: Mês 24 | E20: Mês 30 | F20: Mês 36
A21: 250000 | B21: 0.407 | C21: 0.98 | D21: 1 | E21: 1 | F21: 1
A22: 500000 | B22: 0.016 | C22: 0.635 | D22: 0.998 | E22: 1 | F22: 1
A23: 1000000 | B23: 0 | C23: 0.019 | D23: 0.684 | E23: 0.999 | F23: 1
A24: 2500000 | B24: 0 | C24: 0 | D24: 0 | E24: 0.077 | F24: 0.778
A25: 5000000 | B25: 0 | C25: 0 | D25: 0 | E25: 0 | F25: 0
A26: 10000000 | B26: 0 | C26: 0 | D26: 0 | E26: 0 | F26: 0
A29: C) Composição do ARR por vertical no mês 36 (ano 3)
A30: Vertical | B30: ARR P10 | C30: ARR P50 | D30: ARR média | E30: ARR P90 | F30: Logos ativos (P50)
A31: Varejo (CVM) | B31: 912229 | C31: 1198008 | D31: 1214409 | E31: 1534044 | F31: 28.9
A32: Seguros (SUSEP) | B32: 672504 | C32: 1033683 | D32: 1055051 | E32: 1468965 | F32: 13.2
A33: Bancos/Fintechs (BACEN) | B33: 243518 | C33: 455176 | D33: 468768 | E33: 711425 | F33: 7.1
A34: Utilities (ANEEL) | B34: 49727 | C34: 129752 | D34: 151410 | E34: 288414 | F34: 2
A37: D) Unit Economics — LTV/CAC/Payback (mesmos 20.000 cenários)
A38: Métrica | B38: P10 | C38: P25 | D38: P50 | E38: Média | F38: P75 | G38: P90
A39: LTV (R$, founder-lifetime) | B39: 268138.82 | C39: 332435.46 | D39: 433349.49 | E39: 486609.61 | F39: 572230.12 | G39: 759231.34
A40: CAC — founder-led (R$) | B40: 15536.09 | C40: 15818.09 | D40: 16149.3 | E40: 16167.9 | F40: 16492.53 | G40: 16824.47
A41: LTV/CAC — founder-led (x) | B41: 16.77 | C41: 20.67 | D41: 26.77 | E41: 30.02 | F41: 35.28 | G41: 46.6
A42: Payback — founder-led (meses) | B42: 3.46 | C42: 3.65 | D42: 3.92 | E42: 3.94 | F42: 4.21 | G42: 4.46
A43: CAC — time comercial full-loaded (R$) | B43: 42790.84 | C43: 46478.41 | D43: 52522.53 | E43: 52570.92 | F43: 58576.45 | G43: 62336.69
A44: LTV/CAC — full-loaded (x) | B44: 5.05 | C44: 6.31 | D44: 8.31 | E44: 9.4 | F44: 11.18 | G44: 15
A45: Payback — full-loaded (meses) | B45: 10.07 | C45: 11.2 | D45: 12.72 | E45: 12.81 | F45: 14.28 | G45: 15.68
A48: E) Valuation implícito (ARR × múltiplo simulado)
...

Sheet CFO - Premissas e Metodologia
A1: CFO — Premissas e Metodologia do Motor Quantitativo
A2: Toda premissa de cenário usada na simulação de Monte Carlo e nos modelos de precificação/TAM-SAM-SOM está listada aqui, para que qualquer pessoa (mentor, investidor, o próprio fundador) audite e reproduza o resultado. Nenhuma premissa aqui é 'dado real' — são parâmetros de cenário do CFO.
A4: A) Verticais — janela de lançamento, SAM e ACV
A5: Vertical | B5: Lançamento (mín/moda/máx, meses) | C5: SAM (contas-alvo) | D5: ACV base (R$/ano) | E5: CAC início→maturidade (R$)
A6: Varejo (CVM) | B6: 0 / 0 / 0 (já ativo) | C6: 70 | D6: 45000 | E6: 9.000 → 28.000
A7: Seguros (SUSEP) | B7: 6 / 9 / 14 | C7: 130 | D7: 85000 | E7: 14.000 → 40.000
A8: Bancos/Fintechs (BACEN) | B8: 12 / 15 / 20 | C8: 100 | D8: 70000 | E8: 13.000 → 38.000
A9: Utilities (ANEEL) | B9: 18 / 22 / 28 | C9: 40 | D9: 65000 | E9: 15.000 → 35.000
A11: B) Parâmetros estocásticos globais
A12: Parâmetro | B12: Distribuição | C12: Racional
A13: Ritmo de novos logos/trimestre | B13: Poisson(λ), λ evolui linearmente de ramp_start a ramp_end ao longo de 8 trimestres desde o lançamento da vertical, limitado ao SAM remanescente | C13: Captura curva de adoção em S sem hardcodar um teto — a própria saturação do SAM já limita o crescimento no final
A14: Churn anual de logos | B14: Beta(6,44) → média ≈12% a.a. | C14: Referência para ferramentas de compliance/benchmarking embutidas em workflow (alto custo de troca)
A15: Realização de preço (desconto/prêmio vs. lista) | B15: Uniforme(0,80 ; 1,05) | C15: Negociação comercial em vendas enterprise B2B
A16: Margem bruta | B16: Uniforme(0,87 ; 0,93) | C16: Motor de dados/IA — custo variável = computação de extração/NLP + QA humano
A17: Múltiplo de ARR (valuation) | B17: Triangular(3 ; 6 ; 12), com 5% de probabilidade de cauda estratégica Uniforme(12;23) | C17: Ancorado nos comparáveis da aba de Monte Carlo, seção F — a cauda reflete um cenário de aquisição estratégica (ex.: comp Bureau van Dijk/Moody's)
A18: CAC full-loaded (estresse) | B18: CAC founder-led × Uniforme(2,5 ; 4,0) | C18: Custo de um time comercial estruturado (AE+SDR+marketing), vs. o CAC de fundador (rede quente/mentores)
A19: Número de simulações | B19: 20.000 cenários independentes, seed=42 (reprodutível) | C19: Amostra suficiente para estabilizar percentis extremos (P10/P90)
A22: C) Dados de mercado reais usados como âncora (fonte externa citada)
A23: Dado | B23: Valor | C23: Fonte
A24: SUSEP — entidades fiscalizadas | B24: 356 (20 capitalização, 24 corretores de resseguro, 23 EAPC, 119 resseguradoras + seguradoras) | C24: susep.gov.br (2025)
A25: BACEN — fintechs autorizadas | B25: 308 (2025), alta de 1 (2016) para 258 (2024) | C25: Boletim Demarest / Agência Brasil (dez/2025-jan/2026)
A26: BACEN — fintechs ativas (universo amplo, reguladas+não reguladas) | B26: 2.156 (2025) | C26: Mapeamento de Fintechs Atuantes no Brasil 2025 (Fincatch)
A27: ANEEL — grandes distribuidoras | B27: 33 concessionárias de grande porte (ranking de continuidade) | C27: ABRADEE/ANEEL
A28: B3 — total de companhias listadas | B28: >400 (todos os setores) | C28: B3 / InfoMoney (2025-2026)
A29: Moody's × Bureau van Dijk — múltiplo de aquisição | B29: 22,7x receita (2017, EUR 3 bi) | C29: Global Benefits Vision
A30: SaaS Capital Index — múltiplo público mediano | B30: 3,8x (mar/2026) → 4,8x (mai-jun/2026) | C30: Fungies.io, 2026
A31: NRF — shrink do varejo americano (referência de escala global) | B31: ~US$ 100 bi/ano (universo comparável ao problema brasileiro de R$42,1 bi) | C31: NRF, 2024-2025
A34: D) Ações recomendadas para reduzir a incerteza do modelo (prioridade)
A35: Ação | B35: Reduz incerteza em... | C35: Prazo sugerido
A36: Extrair DFP/ITR da Via S.A. (nota de estoques, 2021-2024) | B36: Teste de caso mais importante do brief (item 3.5) — sensibilidade nº1 do modelo é indiretamente esse dado | C36: Antes do Demo Day, se possível
A37: Extrair as 6 empresas pendentes + série histórica 3-5 anos | B37: Robustez estatística do benchmarking (seção B da aba Aprofundamento CFO) | C37: Até 21/08 (fim do programa)
A38: Validar ACV e SAM com Antonio Nakad (NG Cash) e José Noblecilla (Valor Capital) | B38: Premissas de precificação e de motor horizontal (maior driver de sensibilidade após o múltiplo) | C38: Semana do kickoff (24-25/07)
A39: Confirmar 1ª conversa comercial paga (design partner) | B39: Substitui CAC/ACV assumidos por dado real de negociação | C39: Pós Demo Day, antes de 21/08
A42: Convenção de cor:
A43: Azul = dado real, digitado a partir de fonte citada · Preto = fórmula · Amarelo = placeholder a preencher · Verde = premissa de modelagem do CFO (cenário/estimativa, não é fato verificado — distinta de dado real citado).
